<mujoco model='dex_manip'>

    <asset>
        <include file="../../contactdb/meshes/hammer/meshes.xml"/>
    </asset>

    <!-- ======= WORLD ======= -->
    <worldbody>
        <light directional='false' diffuse='.7 .7 .7' specular='0.03 0.03 0.03' pos='-1 -1.0 4.0' dir='1 1.0 -4'/>
        <geom name='ground' size="1.5 1.5 0.25" pos="0 0 -1" type="plane" contype="1" conaffinity="0" material="groundplane" />

        <!-- ======= CAMERAS ======= -->
        <!--    Camera faces down
                Pos and Frame orientation: right hand thumb rule
                    x - middle, y - index, z - thumb -->
        <camera name="fixed" pos="0 -0.7 0.7" quat="0.92388 0.382683 0 0" />
        <!--<camera name="first_person" pos="0 -0.8 0.8" quat="0.92388 0.382683 0 0" /> --> <!-- (x,y,z):(45,0,0) -->
        <!--<camera name="first_person" pos="0 -0.8 0.8" euler="0.7853982 0 0" /> --> <!-- (x,y,z):(45,0,0) -->
        <camera name="first_person" pos="0 -0.7 0.7" axisangle="1 0 0 0.7853982" /> <!-- (x,y,z):(45,0,0) -->
        <camera name="left" pos="-1.0 0 0.6" axisangle="0.4472136 -0.4472136 -0.7745967 1.8234766" /> <!-- (z,x,y):(-90,60,0) -->
        <camera name="right" pos="1.0 0 0.6" axisangle="0.4472136 0.4472136 0.7745967 1.8234766" /> <!-- (z,x,y):(90,60,0) -->

        <!-- ======= TABLE ======= -->
        <body name="table">
            <!-- <geom size="0.5 0.5 0.025" type="plane" material="table2d" /> --> <!-- Plane has better contacts -->
            <geom name='table_base' size="0.85 0.45 0.025" pos="0 0 -0.025" type="box" material="table_ycb" />
            <geom name='table_leg1' size="0.04 0.5" pos="0.8 0.4 -0.501" quat="0 1 0 0" type="cylinder" contype="0" conaffinity="0" />
            <geom name='table_leg2' size="0.04 0.5" pos="-0.8 0.4 -0.501" quat="0 1 0 0" type="cylinder" contype="0" conaffinity="0" />
            <geom name='table_leg3' size="0.04 0.5" pos="0.8 -0.4 -0.501" quat="0 1 0 0" type="cylinder" contype="0" conaffinity="0" />
            <geom name='table_leg4' size="0.04 0.5" pos="-0.8 -0.4 -0.501" quat="0 1 0 0" type="cylinder" contype="0" conaffinity="0" />
        </body>

        <!-- ======= HAND ======= -->
        <body name="forearm" pos="0 -0.3 0.7" euler="-3.14 0 0">
            <!-- Camera to track hand com 7.5 cm above and 2.5 cm behind the com, at an elevation of 45 deg
            Note that camera xes are wrt the object axis which is different from world axes -->
            <camera name="egocentric" mode="trackcom" pos="0 0.5 0" axisangle="0 0.9238795 0.3826834 3.1415927" /> <!-- (y,x,z):(180,-45,0) -->
            <camera name="egocentric_zoom" mode="trackcom" pos="0 0.15 0.35" axisangle="0 0.9238795 0.3826834 3.1415927" fovy="75" /> <!-- (y,x,z):(180,-45,0) -->
            <joint name="ARTx" pos="0 0 0" axis="1 0 0" type="slide" range="-0.25 0.25" damping="20" />
            <joint name="ARTy" pos="0 0 0" axis="0 -1 0" type="slide" range="0 0.2" damping="20" />
            <joint name="ARTz" pos="0 0 0" axis="0 0 -1" type="slide" range="-0.3 0.5" damping="20" />
            <joint name="ARRx" pos="0 0 0" axis="1 0 0" range="-.75 .75" damping="20" />
            <joint name="ARRy" pos="0 0 0" axis="0 1 0" range="-.75 .75" damping="20" />
            <joint name="ARRz" pos="0 0 0" axis="0 0 1" range="-.75 .75" damping="20" />
            <geom name="mount" type="cylinder" size="0.063 .01" />
            <!-- <geom name="V_forearm" class="D_Vizual" pos="0 -.01 .181" euler="0 0 -1.57"  mesh="forearm_simple" /> -->
            <!-- <geom name="C_forearm1" class="DC_Hand" size="0.05 0.033" pos="0 0 0.29" type="capsule" rgba="0.4 0.5 0.6 0.1" /> -->
            <!-- ======= Allegro ======= -->
            <include file="../../Allegro/right_hand.xml"/>
        </body>



        <!-- ======= OBJECT ======= -->
        <body name="Object" pos="-0.00 0.0 0.0" user="1001 0 2003 27 0 0 0.06 0 0">
            <inertial pos="0 0 0" mass="0.2" diaginertia="8.80012e-05 8.80012e-05 8.80012e-05" />
            <joint name="obj_Tx3" pos="0 0 0" axis="1 0 0" type="slide" limited="false" damping="0" />
            <joint name="obj_Ty3" pos="0 0 0" axis="0 1 0" type="slide" limited="false" damping="0" />
            <joint name="obj_Tz3" pos="0 0 0" axis="0 0 1" type="slide" limited="false" damping="0" />
            <joint name="obj_Rx3" pos="0 0 0" axis="1 0 0" limited="false" damping="0.1" />
            <joint name="obj_Ry3" pos="0 0 0" axis="0 1 0" limited="false" damping="0.1" />
            <joint name="obj_Rz3" pos="0 0 0" axis="0 0 1" limited="false" damping="0.1" />
            <include file="../../contactdb/meshes/hammer/geoms.xml"/>
        </body>
    </worldbody>

    <actuator>
        <general name="A_ARTx" joint="ARTx" ctrlrange="-0.25 0.25" biastype="affine" gainprm="40 0 0" biasprm="0 -20 0" />
        <general name="A_ARTy" joint="ARTy" ctrlrange="0.0 0.2" biastype="affine" gainprm="40 0 0" biasprm="0 -20 0" />
        <general name="A_ARTz" joint="ARTz" ctrlrange="-0.3 0.5" biastype="affine" gainprm="40 0 0" biasprm="0 -20 0" />
        <general name="A_ARRx" joint="ARRx" ctrlrange="-.75 .75" biastype="affine" gainprm="40 0 0" biasprm="0 -20 0" />
        <general name="A_ARRy" joint="ARRy" ctrlrange="-.75 .75" biastype="affine" gainprm="40 0 0" biasprm="0 -20 0" />
        <general name="A_ARRz" joint="ARRz" ctrlrange="-.75 .75" biastype="affine" gainprm="20 0 0" biasprm="0 -20 0" />
    </actuator>

    <include file='../../Allegro/Allegro_assets.xml'/>


</mujoco>
