<mujoco model="allegro_right">
  <!-- <include file='./Allegro_assets.xml'/> -->

  <!-- <worldbody> -->
    <body name="all_palm" quat="1 0 0 1" pos="0 0 0.105" childclass="allegro_right" >
      <!-- <inertial mass="0.4154" pos="0 0 0.000475" diaginertia="1e-4 1e-4 1e-4"/> -->
      <site name="Tch_palm" pos="0 0 0.105"/>
      <geom class="palm_visual" mesh="base_link"/>
      <geom class="palm_collision"/>
      <!-- First finger -->
      <body name="ff_base" pos="0 0.0435 -0.001542" quat="0.999048 -0.0436194 0 0">
        <joint name="ffj0" class="base"/>
        <site name="Tch_ff_base" pos="0 0 0"/>

        <geom class="base_visual"/>
        <geom class="base_collision"/>
        <body name="ff_proximal" pos="0 0 0.0164">
          <joint name="ffj1" class="proximal"/>
          <site name="Tch_ff_proximal" pos="0 0 0.0164"/>
          <geom class="proximal_visual"/>
          <geom class="proximal_collision"/>
          <body name="ff_medial" pos="0 0 0.054">
            <site name="Tch_ff_medial" pos="0 0 0.054"/>
            <joint name="ffj2" class="medial"/>
            <geom class="medial_visual"/>
            <geom class="medial_collision"/>
            <body name="ff_distal" pos="0 0 0.0384">
              <site name="Tch_ff_distal" pos="0 0 0.0384"/>
              <joint name="ffj3" class="distal"/>
              <geom class="distal_visual"/>
              <geom class="distal_collision"/>
              <body name="ff_tip">
                <site name="Tch_ff_tip" pos="0 0 0.0384"/>
                <geom class="fingertip_visual"/>
                <geom class="fingertip_collision"/>
              </body>
            </body>
          </body>
        </body>
      </body>
      <!-- Middle finger -->
      <body name="mf_base" pos="0 0 0.0007">
        <site name="Tch_mf_base" pos="0 0 0.0007"/>
        <joint name="mfj0" class="base"/>
        <geom class="base_visual"/>
        <geom class="base_collision"/>
        <body name="mf_proximal" pos="0 0 0.0164">
          <site name="Tch_mf_proximal" pos="0 0 0.0164"/>
          <joint name="mfj1" class="proximal"/>
          <geom class="proximal_visual"/>
          <geom class="proximal_collision"/>
          <body name="mf_medial" pos="0 0 0.054">
            <site name="Tch_mf_medial" pos="0 0 0.054"/>
            <joint name="mfj2" class="medial"/>
            <geom class="medial_visual"/>
            <geom class="medial_collision"/>
            <body name="mf_distal" pos="0 0 0.0384">
              <site name="Tch_mf_distal" pos="0 0 0.0384"/>
              <joint name="mfj3" class="distal"/>
              <geom class="distal_visual"/>
              <geom class="distal_collision"/>
              <body name="mf_tip">
                <site name="Tch_mf_tip" pos="0 0 0.0384"/>
                <geom class="fingertip_visual"/>
                <geom class="fingertip_collision"/>
              </body>
            </body>
          </body>
        </body>
      </body>
      <!-- Ring finger -->
      <body name="rf_base" pos="0 -0.0435 -0.001542" quat="0.999048 0.0436194 0 0">
        <site name="Tch_rf_base" pos="0 0 0"/>
        <joint name="rfj0" class="base"/>
        <geom class="base_visual"/>
        <geom class="base_collision"/>
        <body name="rf_proximal" pos="0 0 0.0164">
          <site name="Tch_rf_proximal" pos="0 0 0.0164"/>
          <joint name="rfj1" class="proximal"/>
          <geom class="proximal_visual"/>
          <geom class="proximal_collision"/>
          <body name="rf_medial" pos="0 0 0.054">
            <site name="Tch_rf_medial" pos="0 0 0.054"/>
            <joint name="rfj2" class="medial"/>
            <geom class="medial_visual"/>
            <geom class="medial_collision"/>
            <body name="rf_distal" pos="0 0 0.0384">
              <site name="Tch_rf_distal" pos="0 0 0.0384"/>
              <joint name="rfj3" class="distal"/>
              <geom class="distal_visual"/>
              <geom class="distal_collision"/>
              <body name="rf_tip">
                <site name="Tch_rf_tip" pos="0 0 0.0384"/>
                <geom class="fingertip_visual"/>
                <geom class="fingertip_collision"/>
              </body>
            </body>
          </body>
        </body>
      </body>
      <!-- Thumb -->
      <body name="th_base" pos="-0.0182 0.019333 -0.045987" quat="0.477714 -0.521334 -0.521334 -0.477714">
        <joint name="thj0" class="thumb_base"/>
        <site name="Tch_th_base" pos="0 0 0"/>
        <geom class="visual" mesh="link_12.0_right"/>
        <geom class="thumb_base_collision"/>
        <body name="th_proximal" pos="-0.027 0.005 0.0399">
          <site name="Tch_th_proximal" pos="0 0 0"/>
          <joint name="thj1" class="thumb_proximal"/>
          <geom class="visual" mesh="link_13.0"/>
          <geom class="thumb_proximal_collision"/>
          <body name="th_medial" pos="0 0 0.0177">
            <site name="Tch_th_medial" pos="0 0 0"/>
            <joint name="thj2" class="thumb_medial"/>
            <geom class="visual" mesh="link_14.0"/>
            <geom class="thumb_medial_collision"/>
            <body name="th_distal" pos="0 0 0.0514">
              <site name="Tch_th_distal" pos="0 0 0"/>
              <joint name="thj3" class="thumb_distal"/>
              <geom class="visual" mesh="link_15.0"/>
              <geom class="thumb_distal_collision"/>
              <body name="th_tip">
                <site name="Tch_th_tip" pos="0 0 0"/>
                <geom class="thumbtip_visual"/>
                <geom class="thumbtip_collision"/>
              </body>
            </body>
          </body>
        </body>
      </body>
    </body>
  <!-- </worldbody> -->
  

</mujoco>
